Workbook

Sheet 개요
A1: 로그라이크 카드 시스템 기획 (초안)
A3: 목표 | B3: 적을 처치해 경험치를 모으고, 레벨업할 때마다 카드 3장 중 1장을 골라 그 판의 빌드를 만든다. 기존 상점의 '능력치 직접 구매'는 '카드 뽑기 기회 구매'로 바꾼다.
A4: 경험치 바 | B4: HUD 상단(하트 줄 아래)에 얇은 경험치 바 + 'LV 3'. 적 처치 시 경험치 획득 (적별 수치는 '경험치' 시트). 레벨은 한 판 동안 유지, 사망 후 재도전 시 스테이지 시작 시점으로 되돌린다(코인과 같은 규칙).
A5: 레벨업 화면 | B5: 레벨업 순간 게임을 멈추고 카드 3장을 펼친다. ←→로 고르고 Z/Enter로 확정. 카드 = 등급 테두리 + 아이콘(도트) + 이름(영문 픽셀 폰트) + 효과 한 줄 + 현재 단계 칸(Lv 1/3). 한 프레임에 여러 레벨이 오르면 화면을 연달아 띄운다.
A6: 카드 제시 규칙 | B6: ① 3장 서로 다른 카드 ② 이미 가진 특수 카드, 최대 중첩에 도달한 능력치·특수(중첩) 카드, 선행 조건을 못 채운 카드, 이미 가진 필살기보다 낮은 등급의 필살기 카드는 제외 ③ 같은 분류는 최대 2장 ④ 등급은 '등급' 시트 확률로 먼저 뽑고, 그 등급 안에서 카드를 고른다 ⑤ 해당 등급에 남은 카드가 없으면 한 단계 아래 등급으로.
A7: 등급 | B7: 일반 / 희귀 / 영웅 / 전설 4단계. 등급마다 카드 테두리 색과 연출이 다르다. 전설 확률은 스테이지 1/2/3에서 6% / 8% / 10%. ('등급' 시트)
A8: 카드 중복 | B8: 능력치 카드는 최대 단계까지 다시 나온다. 특수 능력 카드는 한 번만 얻는다 (단, 투사체 수·대시 칸처럼 개수로 쌓이는 특수 능력은 예외). 서로 다른 특수 능력은 모두 함께 적용된다. ('중첩 규칙' 시트)
A9: 상점 | B9: 스테이지 클리어 후 상점은 '카드 뽑기 기회' 구매 화면이 된다. 가격은 1회 50코인 고정 (확정). 상점에서 뽑는 카드는 희귀 이상 1장 보장. ('상점' 시트)
A10: 캐릭터 패널 | B10: 상점 화면 왼쪽(또는 일시정지 화면)에 현재 능력치를 아이콘 + 숫자로, 얻은 특수 카드를 16x16 아이콘 격자로 보여 준다. ('캐릭터 패널' 시트)
A11: 기존 동작 변경 (확정) | B11: 현재 대시는 기본으로 무적이다(Player.cpp: 대시 중 피격 무시). 기획상 기본 대시는 무적이 아니고, '무적 대시' 카드(영웅)로 얻는다. 대신 기본 대시에 '대시 칸' 1개를 HUD에 표시하고, 칸이 차면 다시 쓸 수 있게 한다.
A12: 게임 내 표기 | B12: 픽셀 폰트가 영문 대문자/숫자만 지원하므로 카드 이름과 효과 문구는 '게임 표기' 열의 영문을 쓴다. 한글 이름은 기획용.
A13: 파일 보는 법 | B13: '카드 목록'이 본 표다. 등급/분류 열은 목록에서 고르고, 필터로 등급별·분류별로 볼 수 있다. 파란 글씨 = 조정할 수 있는 입력값, 노란 칸 = 결정이 필요한 값. '요약' 시트는 카드 수를 자동으로 센다.
A14: 보스전 (확정) | B14: 보스전에서는 경험치·레벨업 화면이 없다. 대신 보스 체력이 66%, 33% 아래로 내려갈 때(패턴 단계가 바뀔 때) 카드 1장씩, 총 2장을 고른다. 단계 전환 연출 중에 띄워서 전투 템포를 끊지 않는다. 확률은 스테이지 3 열을 쓴다.
A15: 열린 질문 | B15: 사망 후 재도전 시 그 스테이지에서 얻은 카드도 되돌릴지 — 제안: 되돌림 (코인과 같은 규칙)

Sheet 요약
A1: 카드 수 요약 (카드 목록에서 자동 계산)
A3: 분류 \ 등급 | B3: 일반 | C3: 희귀 | D3: 영웅 | E3: 전설 | F3: 합계
A4: 공격 | B4: =COUNTIFS('카드 목록'!$E:$E,$A4,'카드 목록'!$D:$D,"일반") -> 5 | C4: =COUNTIFS('카드 목록'!$E:$E,$A4,'카드 목록'!$D:$D,"희귀") -> 4 | D4: =COUNTIFS('카드 목록'!$E:$E,$A4,'카드 목록'!$D:$D,"영웅") -> 4 | E4: =COUNTIFS('카드 목록'!$E:$E,$A4,'카드 목록'!$D:$D,"전설") -> 3 | F4: =SUM(B4:E4) -> 16
A5: 방어 | B5: =COUNTIFS('카드 목록'!$E:$E,$A5,'카드 목록'!$D:$D,"일반") -> 2 | C5: =COUNTIFS('카드 목록'!$E:$E,$A5,'카드 목록'!$D:$D,"희귀") -> 3 | D5: =COUNTIFS('카드 목록'!$E:$E,$A5,'카드 목록'!$D:$D,"영웅") -> 2 | E5: =COUNTIFS('카드 목록'!$E:$E,$A5,'카드 목록'!$D:$D,"전설") -> 0 | F5: =SUM(B5:E5) -> 7
A6: 이동 | B6: =COUNTIFS('카드 목록'!$E:$E,$A6,'카드 목록'!$D:$D,"일반") -> 2 | C6: =COUNTIFS('카드 목록'!$E:$E,$A6,'카드 목록'!$D:$D,"희귀") -> 2 | D6: =COUNTIFS('카드 목록'!$E:$E,$A6,'카드 목록'!$D:$D,"영웅") -> 0 | E6: =COUNTIFS('카드 목록'!$E:$E,$A6,'카드 목록'!$D:$D,"전설") -> 0 | F6: =SUM(B6:E6) -> 4
A7: 대시 | B7: =COUNTIFS('카드 목록'!$E:$E,$A7,'카드 목록'!$D:$D,"일반") -> 2 | C7: =COUNTIFS('카드 목록'!$E:$E,$A7,'카드 목록'!$D:$D,"희귀") -> 2 | D7: =COUNTIFS('카드 목록'!$E:$E,$A7,'카드 목록'!$D:$D,"영웅") -> 2 | E7: =COUNTIFS('카드 목록'!$E:$E,$A7,'카드 목록'!$D:$D,"전설") -> 1 | F7: =SUM(B7:E7) -> 7
A8: 필살기 | B8: =COUNTIFS('카드 목록'!$E:$E,$A8,'카드 목록'!$D:$D,"일반") -> 2 | C8: =COUNTIFS('카드 목록'!$E:$E,$A8,'카드 목록'!$D:$D,"희귀") -> 2 | D8: =COUNTIFS('카드 목록'!$E:$E,$A8,'카드 목록'!$D:$D,"영웅") -> 1 | E8: =COUNTIFS('카드 목록'!$E:$E,$A8,'카드 목록'!$D:$D,"전설") -> 1 | F8: =SUM(B8:E8) -> 6
A9: 특수 | B9: =COUNTIFS('카드 목록'!$E:$E,$A9,'카드 목록'!$D:$D,"일반") -> 3 | C9: =COUNTIFS('카드 목록'!$E:$E,$A9,'카드 목록'!$D:$D,"희귀") -> 2 | D9: =COUNTIFS('카드 목록'!$E:$E,$A9,'카드 목록'!$D:$D,"영웅") -> 3 | E9: =COUNTIFS('카드 목록'!$E:$E,$A9,'카드 목록'!$D:$D,"전설") -> 1 | F9: =SUM(B9:E9) -> 9
A10: 합계 | B10: =SUM(B4:B9) -> 16 | C10: =SUM(C4:C9) -> 15 | D10: =SUM(D4:D9) -> 12 | E10: =SUM(E4:E9) -> 6 | F10: =SUM(F4:F9) -> 49
A12: 사용자 제안 카드 수 | B12: =COUNTIF('카드 목록'!$L:$L,"사용자*") -> 8
A13: 기존 상점에서 옮긴 카드 | B13: =COUNTIF('카드 목록'!$L:$L,"*기존 상점*") -> 9
A15: 능력치 카드 수 | B15: =COUNTIF('카드 목록'!$F:$F,"능력치") -> 18
A16: 특수 카드 수 | B16: =COUNTIF('카드 목록'!$F:$F,"특수") -> 23
A17: 특수(중첩) 카드 수 | B17: =COUNTIF('카드 목록'!$F:$F,"특수(중첩)") -> 7
A18: 소모 카드 수 | B18: =COUNTIF('카드 목록'!$F:$F,"소모") -> 1

Sheet 등급
A1: 등급별 테두리와 출현 확률
A3: 등급 | B3: 영문 | C3: 테두리 색(HEX) | D3: 색 미리보기 | E3: 테두리 연출 | F3: 스테이지 1 확률 | G3: 스테이지 2 확률 | H3: 스테이지 3 (보스전) 확률 | I3: 행운 카드 1단계당 보정(%p)
A4: 일반 | B4: COMMON | C4: #9AA0B5 | E4: 회색 2px 단색 테두리 | F4: 0.44 | G4: 0.36 | H4: 0.28 | I4: -0.05
A5: 희귀 | B5: RARE | C5: #4FA3FF | E5: 파랑 2px + 모서리 도트 장식 | F5: 0.32 | G5: 0.34 | H5: 0.36 | I5: 0.02
A6: 영웅 | B6: EPIC | C6: #E05CFF | E6: 마젠타 3px + 테두리 위를 빛 한 점이 천천히 돈다 | F6: 0.18 | G6: 0.22 | H6: 0.26 | I6: 0.02
A7: 전설 | B7: LEGEND | C7: #FFC93C | E7: 금색 3px + 반짝임 파티클, 카드가 열릴 때 화면 흰색 플래시 | F7: 0.06 | G7: 0.08 | H7: 0.1 | I7: 0.01
E8: 합계 (100%여야 함) | F8: =SUM(F4:F7) -> 1 | G8: =SUM(G4:G7) -> 1 | H8: =SUM(H4:H7) -> 1 | I8: =SUM(I4:I7) -> 0
A10: 메모
A11: · 확률은 먼저 등급을 뽑는 데 쓴다. 카드 3장 각각 따로 뽑는다.
A12: · 사용자 요청: 전설 확률을 스테이지 1/2/3에서 6% / 8% / 10%로. 나머지 등급도 같이 올려서 일반이 절반 아래가 되게 했다 (게임이 늘어지지 않도록).
A13: · 상점 뽑기는 방금 끝낸 스테이지의 확률 + '희귀 이상 1장 보장'. 3장이 모두 일반으로 나오면 1장을 희귀로 다시 뽑는다.
A14: · 스테이지 3(보스전)은 레벨업 대신 보스 체력 단계가 바뀔 때 카드를 준다 ('경험치' 시트).
A15: · 행운(LUCK) 카드 1단계마다 일반 -5%p, 희귀 +2%p, 영웅 +2%p, 전설 +1%p. (보정 합계가 0이라 전체 합은 100% 유지)
A16: · 영웅 테두리는 배경이 보라 계열이라 보라 대신 밝은 마젠타로 잡았다. 실제 화면에서 보고 조정.
A17: · 확률 값(파란 글씨)은 임시값이다. 플레이테스트 후 조정.

Sheet 카드 목록
A1: ID | B1: 카드 이름 | C1: 게임 표기 | D1: 등급 | E1: 분류 | F1: 종류 | G1: 효과 | H1: 1회당 수치 | I1: 최대 중첩 | J1: 선행 조건 | K1: 아이콘 아이디어 | L1: 출처 | M1: 구현 난이도 | N1: 비고
A2: A01 | B2: 공격력 강화 | C2: ATTACK UP | D2: 일반 | E2: 공격 | F2: 능력치 | G2: 섀도우볼 피해 증가 (공이 커지는 연출 유지) | H2: 피해 +1 | I2: 5 | K2: 주먹 / 보라 공 | L2: 기존 상점 | M2: 하 | N2: 기존 공격력 업그레이드(최대 4)를 5로
A3: A02 | B3: 연사 강화 | C3: FIRE RATE | D3: 일반 | E3: 공격 | F3: 능력치 | G3: 발사 간격 감소 | H3: 간격 -15% | I3: 4 | K3: 공 2개 겹침 | L3: 기존 상점 | M3: 하
A4: A03 | B4: 사거리 증가 | C4: RANGE UP | D4: 일반 | E4: 공격 | F4: 능력치 | G4: 섀도우볼이 더 멀리 날아감 | H4: 수명 +20% | I4: 3 | K4: 화살표 →→ | L4: 기획 추가 | M4: 하
A5: A04 | B5: 탄속 증가 | C5: SHOT SPEED | D5: 일반 | E5: 공격 | F5: 능력치 | G5: 섀도우볼이 더 빨리 날아감 | H5: 속도 +20% | I5: 2 | K5: 속도선이 붙은 공 | L5: 기획 추가 | M5: 하
A6: A05 | B6: 넉백 강화 | C6: KNOCKBACK | D6: 일반 | E6: 공격 | F6: 능력치 | G6: 맞은 적이 더 멀리 밀려남 | H6: 넉백 +50% | I6: 2 | K6: 튕겨 나가는 슬라임 | L6: 기획 추가 | M6: 하
A7: A07 | B7: 치명타 | C7: CRITICAL | D7: 희귀 | E7: 공격 | F7: 능력치 | G7: 일정 확률로 2배 피해 + 노란 숫자 | H7: 확률 +15% | I7: 3 | K7: 번개 / 별 | L7: 기획 추가 | M7: 하 | N7: 최대 45%
A8: A06 | B8: 관통 | C8: PIERCE | D8: 희귀 | E8: 공격 | F8: 특수(중첩) | G8: 적을 맞혀도 사라지지 않고 다음 적까지 관통 | H8: 관통 +1명 | I8: 2 | K8: 공이 박스를 뚫음 | L8: 기획 추가 | M8: 중 | N8: 관통한 적은 같은 공에 다시 안 맞게 기록
A9: A08 | B9: 후방 사격 | C9: BACK SHOT | D9: 희귀 | E9: 공격 | F9: 특수 | G9: 뒤쪽으로도 같은 공을 발사 (피해 50%) | H9: 뒤로 발사 | I9: 1 | K9: 양쪽 화살표 | L9: 기획 추가 | M9: 하 | N9: 멀티샷과 겹치면 뒤로도 같은 수만큼
A10: A09 | B10: 처형자 | C10: EXECUTE | D10: 희귀 | E10: 공격 | F10: 특수 | G10: 체력 30% 이하인 적에게 피해 증가 | H10: 피해 +50% | I10: 1 | K10: 해골 | L10: 기획 추가 | M10: 하 | N10: 보스에게도 적용
A11: A10 | B11: 멀티샷 | C11: MULTI SHOT | D11: 영웅 | E11: 공격 | F11: 특수(중첩) | G11: 한 번에 발사하는 섀도우볼 수 증가 (부채꼴) | H11: 투사체 +1 | I11: 2 | K11: 공 3개 부채꼴 | L11: 사용자 + 기존 상점 | M11: 하 | N11: 사용자: 전설 바로 아래 등급. 중첩 가능한 특수 능력. 이미 구현됨(ShotCount)
A12: A11 | B12: 튕기는 탄 | C12: BOUNCE | D12: 영웅 | E12: 공격 | F12: 특수(중첩) | G12: 벽이나 바닥에 닿으면 1번 튕겨서 계속 날아감 | H12: 튕김 +1 | I12: 2 | K12: 지그재그 공 | L12: 기획 추가 | M12: 중 | N12: 타일 충돌 시 반사
A13: A12 | B13: 폭발탄 | C13: BURST SHOT | D13: 영웅 | E13: 공격 | F13: 특수 | G13: 적중 지점에 폭발 (반경 40px, 피해 50%) | H13: 폭발 | I13: 1 | K13: 터지는 별 | L13: 기획 추가 | M13: 중 | N13: 기존 Effects.Burst 재사용
A14: A13 | B14: 저주탄 | C14: CURSE | D14: 영웅 | E14: 공격 | F14: 특수 | G14: 맞은 적이 3초 동안 받는 모든 피해 증가 (보라 표식) | H14: 받는 피해 +25% | I14: 1 | K14: 보라 눈 | L14: 기획 추가 | M14: 중
A15: A14 | B15: 유도탄 | C15: HOMING | D15: 전설 | E15: 공격 | F15: 특수 | G15: 섀도우볼이 가장 가까운 적을 향해 휘어서 날아감. 대신 공격력 -1 (최소 1) | H15: 유도 / 공격력 -1 | I15: 1 | K15: 휘어진 화살표 + 과녁 | L15: 사용자 | M15: 중 | N15: 사용자: 전설 카드. 밸런스: 맞히기 쉬운 대신 공격력 -1 (최소 1)
A16: A15 | B16: 분열탄 | C16: SPLIT | D16: 전설 | E16: 공격 | F16: 특수 | G16: 적중 시 작은 공 3개로 갈라져 주변 적을 공격 (피해 40%) | H16: 분열 3개 | I16: 1 | K16: 공이 셋으로 갈라짐 | L16: 기획 추가 | M16: 중 | N16: 분열한 공은 다시 분열하지 않음
A17: A16 | B17: 차지샷 | C17: CHARGE SHOT | D17: 전설 | E17: 공격 | F17: 특수 | G17: Z를 1초 누르고 떼면 3배 크기·3배 피해의 관통 공 발사 | H17: 차지 | I17: 1 | K17: 커다란 공 + 게이지 | L17: 기획 추가 | M17: 상 | N17: 누르고 있는 동안 연사는 멈춤. 조작 변화가 커서 전설
A18: D01 | B18: 최대 하트 | C18: MAX HEART | D18: 일반 | E18: 방어 | F18: 능력치 | G18: 최대 하트 +1 (그 하트도 채워 줌) | H18: 하트 +1 | I18: 4 | K18: 하트 | L18: 기존 상점 | M18: 하
A19: D02 | B19: 회복 | C19: HEAL | D19: 일반 | E19: 방어 | F19: 소모 | G19: 즉시 하트 2개 회복 | H19: 회복 2 | I19: 99 | J19: 하트가 가득 차 있지 않을 것 | K19: 하트 + 십자 | L19: 기획 추가 | M19: 하 | N19: 소모형. 하트가 가득이면 제시하지 않음
A20: D03 | B20: 무적 시간 증가 | C20: LONG GUARD | D20: 희귀 | E20: 방어 | F20: 능력치 | G20: 피격 후 무적 시간 증가 | H20: 무적 +50% | I20: 2 | K20: 깜빡이는 유령 | L20: 기획 추가 | M20: 하
A21: D04 | B21: 영혼 흡수 | C21: SOUL DRAIN | D21: 희귀 | E21: 방어 | F21: 특수 | G21: 적 12마리를 처치할 때마다 하트 1개 회복 | H21: 12킬당 1 | I21: 1 | K21: 하트로 빨려드는 영혼 | L21: 기획 추가 | M21: 하
A22: D05 | B22: 가시 반격 | C22: THORNS | D22: 희귀 | E22: 방어 | F22: 특수 | G22: 몸통으로 부딪힌 적에게 피해 3 | H22: 반격 3 | I22: 1 | K22: 가시 달린 하트 | L22: 기획 추가 | M22: 하
A23: D06 | B23: 그림자 보호막 | C23: SHIELD | D23: 영웅 | E23: 방어 | F23: 특수 | G23: 스테이지마다 피해 1번을 막아 줌 (몸 주위 보라 막) | H23: 1회/스테이지 | I23: 1 | K23: 방패 | L23: 기획 추가 | M23: 중
A24: D07 | B24: 추가 목숨 | C24: EXTRA LIFE | D24: 영웅 | E24: 방어 | F24: 특수(중첩) | G24: 목숨 +1 | H24: 목숨 +1 | I24: 3 | K24: 유령 + 1UP | L24: 기존 상점 | M24: 하
A25: M01 | B25: 이동 속도 | C25: MOVE SPEED | D25: 일반 | E25: 이동 | F25: 능력치 | G25: 달리는 속도 증가 | H25: +0.45px/프레임 | I25: 3 | K25: 신발 | L25: 기존 상점 | M25: 하
A26: M02 | B26: 점프력 | C26: JUMP UP | D26: 일반 | E26: 이동 | F26: 능력치 | G26: 점프 높이 증가 | H26: 점프 +8% | I26: 2 | K26: 위 화살표 | L26: 기획 추가 | M26: 하 | N26: 발판 배치를 건너뛰지 않도록 2단계까지만
A27: M03 | B27: 다단 점프 | C27: AIR JUMP | D27: 희귀 | E27: 이동 | F27: 특수(중첩) | G27: 공중에서 한 번 더 점프 (2단계 = 삼단 점프) | H27: 공중 점프 +1 | I27: 2 | K27: 구름 위 화살표 | L27: 기존 상점 | M27: 하 | N27: 기존 이단 점프(최대 1)를 2로
A28: M04 | B28: 유령 부유 | C28: FLOAT | D28: 희귀 | E28: 이동 | F28: 특수 | G28: 공중에서 점프 키를 누르고 있으면 천천히 떨어짐 | H28: 낙하 -50% | I28: 1 | K28: 깃털 / 흔들리는 꼬리 | L28: 기획 추가 | M28: 중 | N28: 겐가 테마에 맞는 이동기
A29: S01 | B29: 대시 거리 | C29: DASH RANGE | D29: 일반 | E29: 대시 | F29: 능력치 | G29: 대시로 이동하는 거리 증가 | H29: 거리 +25% | I29: 2 | K29: 긴 잔상 | L29: 사용자 | M29: 하
A30: S02 | B30: 대시 충전 | C30: DASH RECHARGE | D30: 일반 | E30: 대시 | F30: 능력치 | G30: 빈 대시 칸이 다시 차는 시간 감소 | H30: 충전 -20% | I30: 2 | K30: 시계 + 칸 | L30: 기획 추가 | M30: 하 | N30: 기본 충전 시간 약 0.6초
A31: S03 | B31: 대시 칸 추가 | C31: DASH CHARGE | D31: 희귀 | E31: 대시 | F31: 특수(중첩) | G31: 대시 칸 +1 (연속으로 대시 가능, HUD에 칸 표시) | H31: 대시 칸 +1 | I31: 2 | K31: 칸 3개 | L31: 사용자 | M31: 중 | N31: 사용자: 대시 가능 칸 + 횟수 증가. 기본 1칸 → 최대 3칸. 중첩 가능한 특수 능력
A32: S04 | B32: 공중 대시 | C32: AIR DASH | D32: 희귀 | E32: 대시 | F32: 특수 | G32: 착지 전 공중 대시 가능 횟수 +1 | H32: 공중 +1 | I32: 1 | K32: 날개 + 잔상 | L32: 기획 추가 | M32: 하 | N32: 대시 칸과 별개 제한 (지금은 공중 1번)
A33: S05 | B33: 무적 대시 | C33: PHASE DASH | D33: 영웅 | E33: 대시 | F33: 특수 | G33: 대시하는 동안 모든 피해를 무시하고 적을 통과 | H33: 대시 무적 | I33: 1 | K33: 반투명 유령 | L33: 사용자 | M33: 하 | N33: 확정: 기본 대시는 무적이 아니다. 지금 코드의 기본 무적을 이 카드로 옮긴다
A34: S06 | B34: 그림자 돌진 | C34: SHADOW RUSH | D34: 영웅 | E34: 대시 | F34: 특수 | G34: 대시로 통과한 적에게 피해 (공격력 x2) | H34: 돌진 피해 | I34: 1 | K34: 칼날 잔상 | L34: 기획 추가 | M34: 중 | N34: 무적 대시와 시너지 (선행 조건은 두지 않음)
A35: S07 | B35: 잔상 폭발 | C35: AFTERIMAGE | D35: 전설 | E35: 대시 | F35: 특수 | G35: 대시를 시작한 자리에 잔상이 남고 0.5초 뒤 폭발 (공격력 x3) | H35: 잔상 폭발 | I35: 1 | K35: 유령 실루엣 + 별 | L35: 기획 추가 | M35: 중 | N35: 기존 대시 잔상 연출 재사용
A36: U01 | B36: 게이지 충전 | C36: GAUGE UP | D36: 일반 | E36: 필살기 | F36: 능력치 | G36: 필살기 게이지가 더 빨리 참 | H36: 충전 +20% | I36: 3 | K36: 게이지 막대 ↑ | L36: 기존 상점 | M36: 하 | N36: 기존 ULTIMATE POWER를 위력/충전으로 나눔
A37: U02 | B37: 필살기 위력 | C37: ULT POWER | D37: 희귀 | E37: 필살기 | F37: 능력치 | G37: 장착한 필살기의 피해 증가 | H37: 피해 +30% | I37: 3 | K37: 폭발 아이콘 | L37: 기존 상점 | M37: 하
A38: U03 | B38: 시작 게이지 | C38: HEAD START | D38: 일반 | E38: 필살기 | F38: 특수 | G38: 스테이지를 시작할 때 게이지 30%를 채우고 시작 | H38: 시작 30% | I38: 1 | K38: 게이지 1/3 | L38: 기획 추가 | M38: 하
A39: U10 | B39: 필살기: 섀도우 레인 | C39: SHADOW RAIN | D39: 희귀 | E39: 필살기 | F39: 특수 | G39: 3초 동안 화면 위에서 그림자 탄이 적에게 쏟아짐 | H39: 필살기 교체 | I39: 1 | J39: 가진 필살기보다 높은 등급 | K39: 떨어지는 공 | L39: 사용자 | M39: 중 | N39: 필살기 시트 참고
A40: U11 | B40: 필살기: 블랙홀 | C40: BLACK HOLE | D40: 영웅 | E40: 필살기 | F40: 특수 | G40: 앞쪽에 블랙홀을 4초 동안 열어 적을 끌어모으며 계속 피해, 적 투사체 흡수 | H40: 필살기 교체 | I40: 1 | J40: 가진 필살기보다 높은 등급 | K40: 소용돌이 | L40: 사용자 | M40: 상 | N40: 필살기 시트 참고
...

Sheet 중첩 규칙
A1: 카드 중복과 특수 능력 조합 규칙
A3: 종류 | B3: 다시 나오는가 | C3: 규칙
A4: 능력치 | B4: 최대 중첩까지 계속 나옴 | C4: 공격력, 연사, 이동 속도처럼 수치만 올리는 카드. 같은 카드를 여러 번 골라 단계를 쌓는다. 최대 단계면 제시 목록에서 빠진다.
A5: 특수 | B5: 한 번 얻으면 다시 안 나옴 | C5: 유도탄, 폭발탄, 무적 대시처럼 '능력이 하나 생기는' 카드. 같은 카드는 한 장만 얻지만, 서로 다른 특수 카드는 몇 장이든 함께 가질 수 있고 효과가 전부 동시에 적용된다.
A6: 특수(중첩) | B6: 최대 중첩까지 계속 나옴 | C6: 특수 능력이지만 개수로 쌓이는 것: 멀티샷(투사체 수), 대시 칸, 공중 점프, 공중 대시, 관통, 튕김, 추가 목숨, 다시 뽑기.
A7: 소모 | B7: 몇 번이든 나옴 | C7: 회복처럼 즉시 효과만 있는 카드. 조건(하트가 가득이 아닐 것)이 맞을 때만 제시.
A9: 특수 능력 조합 (서로 다른 특수 능력은 모두 겹쳐서 적용)
A10: 조합 | B10: 결과 | C10: 제한 (과부하·무한 연쇄 방지)
A11: 멀티샷 + 모든 공 능력 | B11: 부채꼴로 나간 공 하나하나에 유도·관통·튕김·폭발·저주·분열이 모두 붙는다 | C11: -
A12: 유도탄 + 튕기는 탄 | B12: 튕긴 뒤에도 다시 가까운 적을 찾아 휜다 | C12: -
A13: 유도탄 + 분열탄 | B13: 분열한 작은 공도 유도된다 | C13: -
A14: 관통 + 분열탄 | B14: 관통하면서 처음 맞힌 적에게서만 분열 | C14: 공 하나당 분열은 1번
A15: 폭발탄 + 분열탄 | B15: 본래 공은 폭발 + 분열, 분열 조각은 폭발하지 않음 | C15: 분열 조각은 폭발·분열 없음 (연쇄 방지)
A16: 저주탄 + 폭발/분열 | B16: 폭발·분열 조각에 맞은 적에게도 저주 표식 | C16: -
A17: 치명타 + 모든 피해 | B17: 섀도우볼, 분열 조각, 폭발, 돌진, 잔상 폭발 모두 치명타 판정 | C17: 필살기는 치명타 없음
A18: 차지샷 + 공 능력 | B18: 차지 공에 모든 공 능력 적용 | C18: 차지 공도 분열은 1번
A19: 후방 사격 + 멀티샷 | B19: 뒤로도 같은 수만큼 발사 (피해 50%) | C19: -
A20: 무적 대시 + 그림자 돌진 + 잔상 폭발 | B20: 피해 없이 적을 뚫고 지나가며 베고, 출발 지점은 폭발 | C20: -
A21: 대시 칸 + 대시 계열 | B21: 칸마다 돌진·잔상 폭발이 따로 발동 | C21: 잔상은 화면에 최대 3개
... A24: 최후의 저항 + 그림자 보호막 | B24: 보호막이 있는 동안 하트 1개로 버티며 강화 유지 | C24: -

Sheet 필살기
A1: 필살기 종류 (1개만 장착, 높은 등급 카드를 고르면 교체)
A3: 등급 | B3: 필살기 | C3: 게임 표기 | D3: 얻는 방법 | E3: 동작 | F3: 일반 적 피해 | G3: 보스 피해 | H3: 지속 시간(초) | I3: 연출 아이디어
A4: 기본 | B4: 섀도우 펄스 | C4: SHADOW PULSE | D4: 처음부터 보유 | E4: 화면 전체에 충격파 한 번. 화면 안의 적 전부에게 피해 (지금 필살기 그대로) | F4: 6 | G4: 20 | H4: 0 | I4: 지금 연출 유지 (화면 흰색 플래시 + 링)
A5: 희귀 | B5: 섀도우 레인 | C5: SHADOW RAIN | D5: 카드 U10 | E5: 3초 동안 화면 위에서 그림자 탄 18발이 화면 안의 적에게 나눠 떨어짐 | F5: 3 | G5: 2 | H5: 3 | I5: 하늘이 어두워지고 보라 탄이 비처럼 내림
A6: 영웅 | B6: 블랙홀 | C6: BLACK HOLE | D6: 카드 U11 | E6: 바라보는 방향 200px 앞에 블랙홀. 4초 동안 주변 적을 끌어당기고 0.25초마다 피해, 닿은 적 투사체 흡수 | F6: 1.5 | G6: 3 | H6: 4 | I6: 검은 원 + 빨려드는 도트 파티클, 화면 살짝 흔들림
A7: 전설 | B7: 나이트메어 | C7: NIGHTMARE | D7: 카드 U12 | E7: 4초 동안 적·투사체·보스 패턴을 멈춤. 그동안 플레이어 무적, 섀도우볼 피해 2배. 끝날 때 화면 전체 피해 1번 | F7: 8 | G7: 30 | H7: 4 | I7: 화면 색 반전(흑백 + 보라), 겐가의 눈만 빛남
E8: 한 번 쓸 때 총 피해 (일반 적 1명 기준, 지속형은 타격 횟수 반영)
E9: 타격 횟수 가정 → 아래 행
B10: 필살기 | C10: 타격 횟수(가정) | D10: 일반 적 총 피해 | E10: 보스 총 피해
B11: =B4 -> 섀도우 펄스 | C11: 1 | D11: =F4*C11 -> 6 | E11: =G4*1 -> 20
B12: =B5 -> 섀도우 레인 | C12: 2 | D12: =F5*C12 -> 6 | E12: =G5*18 -> 36
B13: =B6 -> 블랙홀 | C13: 16 | D13: =F6*C13 -> 24 | E13: =G6*16 -> 48
B14: =B7 -> 나이트메어 | C14: 1 | D14: =F7*C14 -> 8 | E14: =G7 -> 30
B15: 가정: 섀도우 레인은 한 적이 평균 2발, 보스는 18발 전부 맞음 / 블랙홀은 4초 ÷ 0.25초 = 16타 / 나이트메어의 보스 피해는 마지막 일격만 셈(멈춘 동안 2배 공격은 별도). 필살기 위력 카드(U02)는 위 값에 곱한다.

Sheet 경험치
A1: 경험치 설계 (적 수는 StageBuilder.cpp 기준)
A3: 적 | B3: 처치 경험치 | C3: 스테이지 1 수 | D3: 스테이지 2 수 | E3: 스테이지 1 경험치 | F3: 스테이지 2 경험치 | H3: 레벨업 필요 경험치 = 시작값 + 증가량 x (레벨 - 1)
A4: 슬라임 (Slime) | B4: 2 | C4: 9 | D4: 12 | E4: =B4*C4 -> 18 | F4: =B4*D4 -> 24 | H4: 시작값 | I4: 6
A5: 박쥐 (Bat) | B5: 2 | C5: 0 | D5: 7 | E5: =B5*C5 -> 0 | F5: =B5*D5 -> 14 | H5: 증가량 | I5: 3
A6: 늑대 (Hound) | B6: 4 | C6: 3 | D6: 6 | E6: =B6*C6 -> 12 | F6: =B6*D6 -> 24 | H6: 모두 처치 비율 | I6: 0.85 | J6: 실제로는 적을 다 잡지 못하므로 85%만 잡는다고 가정
A7: 마법사 (Caster) | B7: 4 | C7: 2 | D7: 5 | E7: =B7*C7 -> 8 | F7: =B7*D7 -> 20
A8: 합계 | C8: =SUM(C4:C7) -> 14 | D8: =SUM(D4:D7) -> 30 | E8: =SUM(E4:E7) -> 38 | F8: =SUM(F4:F7) -> 82
A9: 레벨 | B9: 다음 레벨까지 | C9: 누적 필요 | H9: 예상 결과
A10: 1 | B10: =$I$4+$I$5*(A10-1) -> 6 | C10: =B10 -> 6 | H10: 스테이지 1 끝 누적 경험치 | I10: =E8*I6 -> 32.3
A11: 2 | B11: =$I$4+$I$5*(A11-1) -> 9 | C11: =C10+B11 -> 15 | H11: 스테이지 1 끝 레벨 | I11: =IFERROR(MATCH(I10,$C$10:$C$24,1),0)+1 -> 4
A12: 3 | B12: =$I$4+$I$5*(A12-1) -> 12 | C12: =C11+B12 -> 27 | H12: 스테이지 2 끝 누적 경험치 | I12: =(E8+F8)*I6 -> 102
A13: 4 | B13: =$I$4+$I$5*(A13-1) -> 15 | C13: =C12+B13 -> 42 | H13: 스테이지 2 끝 레벨 | I13: =IFERROR(MATCH(I12,$C$10:$C$24,1),0)+1 -> 7
A14: 5 | B14: =$I$4+$I$5*(A14-1) -> 18 | C14: =C13+B14 -> 60 | H14: 레벨업 카드 수 (보스 전) | I14: =I13-1 -> 6
A15: 6 | B15: =$I$4+$I$5*(A15-1) -> 21 | C15: =C14+B15 -> 81 | H15: 보스전 카드 (체력 66%, 33%) | I15: 2
A16: 7 | B16: =$I$4+$I$5*(A16-1) -> 24 | C16: =C15+B16 -> 105 | H16: 한 판 카드 총합 (상점 제외) | I16: =I14+I15 -> 8
A17: 8 | B17: =$I$4+$I$5*(A17-1) -> 27 | C17: =C16+B17 -> 132
A18: 9 | B18: =$I$4+$I$5*(A18-1) -> 30 | C18: =C17+B18 -> 162 | H18: 목표: 스테이지 1에서 2~3장, 스테이지 2까지 합쳐 6장 안팎, 보스전 2장. 스테이지 2 적이 2배라 후반 레벨이 몰리지 않도록 증가량으로 조절.
A19: 10 | B19: =$I$4+$I$5*(A19-1) -> 33 | C19: =C18+B19 -> 195
A20: 11 | B20: =$I$4+$I$5*(A20-1) -> 36 | C20: =C19+B20 -> 231
A21: 12 | B21: =$I$4+$I$5*(A21-1) -> 39 | C21: =C20+B21 -> 270
A22: 13 | B22: =$I$4+$I$5*(A22-1) -> 42 | C22: =C21+B22 -> 312
A23: 14 | B23: =$I$4+$I$5*(A23-1) -> 45 | C23: =C22+B23 -> 357
A24: 15 | B24: =$I$4+$I$5*(A24-1) -> 48 | C24: =C23+B24 -> 405

Sheet 상점
A1: 상점: 카드 뽑기 기회 구매
A3: 뽑기 가격 | B3: 50 | C3: 확정: 1회 50코인 고정. 오르는 가격은 0 (나중에 바꾸고 싶으면 B4만 고치면 된다)
A4: 뽑을 때마다 오르는 가격 | B4: 0
A5: 가격 규칙 | B5: 50코인 고정 (확정)
A7: 뽑기 회차 | B7: 이번 가격 | C7: 누적 가격 | E7: 상점 | F7: 그 판에서 모은 코인 | G7: 뽑을 수 있는 횟수 | H7: 남는 코인
A8: 1 | B8: =$B$3+$B$4*(A8-1) -> 50 | C8: =B8 -> 50 | E8: 스테이지 1 뒤 | F8: 61 | G8: =IFERROR(MATCH(F8,$C$8:$C$13,1),0) -> 1 | H8: =F8-IF(G8=0,0,INDEX($C$8:$C$13,G8)) -> 11
A9: 2 | B9: =$B$3+$B$4*(A9-1) -> 50 | C9: =C8+B9 -> 100 | E9: 스테이지 2 뒤 (남은 코인 포함) | F9: =H8+68 -> 79 | G9: =IFERROR(MATCH(F9,$C$8:$C$13,1),0) -> 1 | H9: =F9-IF(G9=0,0,INDEX($C$8:$C$13,G9)) -> 29
A10: 3 | B10: =$B$3+$B$4*(A10-1) -> 50 | C10: =C9+B10 -> 150
A11: 4 | B11: =$B$3+$B$4*(A11-1) -> 50 | C11: =C10+B11 -> 200
A12: 5 | B12: =$B$3+$B$4*(A12-1) -> 50 | C12: =C11+B12 -> 250
A13: 6 | B13: =$B$3+$B$4*(A13-1) -> 50 | C13: =C12+B13 -> 300
A16: 상점 화면 구성 (제안)
A17: 왼쪽 | B17: 캐릭터 패널: 겐가 도트 + 능력치 아이콘 줄 + 얻은 카드 아이콘 격자 ('캐릭터 패널' 시트)
A18: 가운데 | B18: DRAW CARD (가격 표시) 버튼. 누르면 그 자리에서 카드 3장이 펼쳐지고 하나를 고른다. 희귀 이상 1장 보장
A19: 가운데 아래 | B19: HEAL 2 HEARTS 20코인 (하트가 가득이면 숨김) — 카드 운이 나빠도 회복할 길을 남긴다
A20: 오른쪽 아래 | B20: NEXT STAGE 출발
A21: 봇(bot=1) | B21: 검증용 봇: 살 수 있는 만큼 뽑고, 카드는 등급 높은 것 → 공격 분류 순으로 고른다
A22: 탐욕 카드 | B22: 탐욕(코인 +25%)을 2단계 찍으면 스테이지 1 코인이 61 → 약 92개, 상점에서 1번 뽑고 남는다

Sheet 캐릭터 패널
A1: 캐릭터 패널 (상점 왼쪽 / 일시정지 화면)
A3: 순서 | B3: 표시 항목 | C3: 게임 표기 | D3: 아이콘 (16x16 도트) | E3: 표시 방식 | F3: 관련 카드
A4: 1 | B4: 레벨 | C4: LV | D4: 별 | E4: LV 5 + 작은 경험치 바 | F4: -
A5: 2 | B5: 공격력 | C5: ATK | D5: 주먹 | E5: 숫자 (예: 3) | F5: A01
A6: 3 | B6: 연사 | C6: RATE | D6: 공 2개 | E6: 초당 발사 수 (예: 3.2/S) | F6: A02
A7: 4 | B7: 투사체 | C7: SHOT | D7: 공 3개 부채꼴 | E7: x2 (1이면 숨김) | F7: A10, A08
A8: 5 | B8: 사거리 | C8: RANGE | D8: 화살표 | E8: 막대 3칸 | F8: A03, A04
A9: 6 | B9: 하트 | C9: HP | D9: 하트 | E9: 하트 아이콘 개수 | F9: D01, D02
A10: 7 | B10: 목숨 | C10: LIFE | D10: 유령 | E10: x3 | F10: D07
A11: 8 | B11: 이동 | C11: SPD | D11: 신발 | E11: 막대 3칸 | F11: M01
A12: 9 | B12: 점프 | C12: JUMP | D12: 구름 | E12: 공중 점프 횟수 (x1) | F12: M02, M03
A13: 10 | B13: 대시 | C13: DASH | D13: 잔상 | E13: 대시 칸 개수 (HUD와 같은 칸 모양) | F13: S01~S04
A14: 11 | B14: 필살기 | C14: ULT | D14: 장착한 필살기 아이콘 | E14: 필살기 이름 + 등급 테두리 | F14: U10~U12
A15: 12 | B15: 얻은 특수 카드 | C15: SKILLS | D15: 카드별 아이콘 | E15: 4열 격자, 아이콘 테두리 = 카드 등급 색, 겹친 단계는 오른쪽 아래 작은 숫자 | F15: 능력치가 아닌 카드 전부 (관통, 유도, 무적 대시 등)
A18: 커서를 아이콘에 올리면 아래에 카드 이름과 효과 한 줄을 띄운다 (상점에서 ↑↓로 패널로 이동).
